Workbook

Sheet Sheet1
A1: id | B1: number | C1: item_number | D1: unit_of_measure | E1: active | F1: is_crimp | G1: label_spec | H1: description | I1: notes | J1: deleted_at | K1: created_at | L1: updated_at | M1: id
A2: 1 | B2: 189-10004 | C2: 189-10004 | D2: ea | E2: 1 | F2: 0 | G2: - | H2: STS H-CL-181-1222-90/9 | J2: 0000-00-00 00:00:00 | K2: 46120.859 | L2: 0000-00-00 00:00:00 | M2: 1
A3: 2 | B3: 189-10005 | C3: 189-10005 | D3: ea | E3: 1 | F3: 0 | G3: - | H3: STS H-CL-181-1224-90/9 | J3: 0000-00-00 00:00:00 | K3: 46120.859 | L3: 0000-00-00 00:00:00 | M3: 2
A4: 3 | B4: 189-10006 | C4: 189-10006 | D4: ea | E4: 1 | F4: 0 | G4: - | H4: STS H-CL-181-1226-90/9 | J4: 0000-00-00 00:00:00 | K4: 46120.859 | L4: 0000-00-00 00:00:00 | M4: 3
A5: 4 | B5: 189-10009 | C5: 189-10009 | D5: ea | E5: 1 | F5: 0 | G5: - | H5: STS H-CL-181-2222-90/9 | J5: 0000-00-00 00:00:00 | K5: 46120.859 | L5: 0000-00-00 00:00:00 | M5: 4
A6: 5 | B6: 189-10010 | C6: 189-10010 | D6: ea | E6: 1 | F6: 0 | G6: - | H6: STS H-CL-181-2222-90/9-10 | J6: 0000-00-00 00:00:00 | K6: 46120.859 | L6: 0000-00-00 00:00:00 | M6: 5
A7: 6 | B7: 189-10011 | C7: 189-10011 | D7: ea | E7: 1 | F7: 0 | G7: - | H7: STS H-CL-181-3222-0/9 | J7: 0000-00-00 00:00:00 | K7: 46120.859 | L7: 0000-00-00 00:00:00 | M7: 6
A8: 7 | B8: 189-10012 | C8: 189-10012 | D8: ea | E8: 1 | F8: 0 | G8: - | H8: STS H-CL-181-3222-90/9 | J8: 0000-00-00 00:00:00 | K8: 46120.859 | L8: 0000-00-00 00:00:00 | M8: 7
A9: 8 | B9: 189-10044 | C9: 189-10044 | D9: ea | E9: 1 | F9: 0 | G9: NAS1745-1 | H9: STS H-C-1 | J9: 0000-00-00 00:00:00 | K9: 46120.859 | L9: 0000-00-00 00:00:00 | M9: 8
A10: 9 | B10: 189-10046 | C10: 189-10046 | D10: ea | E10: 1 | F10: 0 | G10: - | H10: STS H-C110-35 | J10: 0000-00-00 00:00:00 | K10: 46120.859 | L10: 0000-00-00 00:00:00 | M10: 9
A11: 10 | B11: 189-10048 | C11: 189-10048 | D11: ea | E11: 1 | F11: 0 | G11: - | H11: STS H-C-110-41 | J11: 0000-00-00 00:00:00 | K11: 46120.859 | L11: 0000-00-00 00:00:00 | M11: 10
A12: 11 | B12: 189-10049 | C12: 189-10049 | D12: ea | E12: 1 | F12: 0 | G12: - | H12: STS H-C-112 | J12: 0000-00-00 00:00:00 | K12: 46120.859 | L12: 0000-00-00 00:00:00 | M12: 11
A13: 12 | B13: 189-10050 | C13: 189-10050 | D13: ea | E13: 1 | F13: 0 | G13: - | H13: STS H-C-113 | J13: 0000-00-00 00:00:00 | K13: 46120.859 | L13: 0000-00-00 00:00:00 | M13: 12
... A432: 431 | B432: 189-10663 | C432: 189-10663 | D432: ea | E432: 1 | F432: 0 | G432: - | H432: STS H-ML-18-9-M | J432: 0000-00-00 00:00:00 | K432: 46120.859 | L432: 0000-00-00 00:00:00 | M432: 431

Sheet Sheet2
A1: part_id | B1: sample_price | C1: workstation_type | D1: effective_date | E1: active | F1: comments | G1: id
A2: 189-10004 | B2: 0.5 | C2: table' | D2: 46113 | E2: 1 | G2: =VLOOKUP(A2,Sheet1!B:M,12,FALSE) -> 1
A3: 189-10005 | B3: 0.5 | C3: table' | D3: 46113 | E3: 1 | G3: =VLOOKUP(A3,Sheet1!B:M,12,FALSE) -> 2
A4: 189-10006 | B4: 0.5 | C4: table' | D4: 46113 | E4: 1 | G4: =VLOOKUP(A4,Sheet1!B:M,12,FALSE) -> 3
A5: 189-10009 | B5: 0.5 | C5: table' | D5: 46113 | E5: 1 | G5: =VLOOKUP(A5,Sheet1!B:M,12,FALSE) -> 4
A6: 189-10010 | B6: 0.5 | C6: table' | D6: 46113 | E6: 1 | G6: =VLOOKUP(A6,Sheet1!B:M,12,FALSE) -> 5
A7: 189-10011 | B7: 0.5 | C7: table' | D7: 46113 | E7: 1 | G7: =VLOOKUP(A7,Sheet1!B:M,12,FALSE) -> 6
A8: 189-10012 | B8: 0.5 | C8: table' | D8: 46113 | E8: 1 | G8: =VLOOKUP(A8,Sheet1!B:M,12,FALSE) -> 7
A9: 189-10044 | B9: 0.5 | C9: table' | D9: 46113 | E9: 1 | G9: =VLOOKUP(A9,Sheet1!B:M,12,FALSE) -> 8
A10: 189-10046 | B10: 0.5 | C10: table' | D10: 46113 | E10: 1 | G10: =VLOOKUP(A10,Sheet1!B:M,12,FALSE) -> 9
A11: 189-10048 | B11: 0.5 | C11: table' | D11: 46113 | E11: 1 | G11: =VLOOKUP(A11,Sheet1!B:M,12,FALSE) -> 10
A12: 189-10049 | B12: 0.5 | C12: table' | D12: 46113 | E12: 1 | G12: =VLOOKUP(A12,Sheet1!B:M,12,FALSE) -> 11
A13: 189-10050 | B13: 0.5 | C13: table' | D13: 46113 | E13: 1 | G13: =VLOOKUP(A13,Sheet1!B:M,12,FALSE) -> 12
... A435: 189-10663 | B435: 0.5 | C435: table' | D435: 46113 | E435: 1 | G435: =VLOOKUP(A435,Sheet1!B:M,12,FALSE) -> 431

Sheet Sheet3
A1: price_id | B1: min_quantity | C1: max_quantity | D1: tier_price | E1: Note 1 | F1: Note 2 | G1: id_db | H1: extra_notes | I1: is_machine_or_semiauto
A2: 189-10004 | B2: 1000 | C2: 10999 | D2: 56.03 | E2: W/407-30008 and 407-30010 and 408-20010 | F2: OK | G2: =VLOOKUP(A2,Sheet2!A:G,7,FALSE) -> 1 | I2: =IF(LEFT(E2,1)="T","Semi-Automatica",IF(LEFT(E2,2)="ST","Maquina",""))
A3: 189-10004 | B3: 11000 | C3: 49999 | D3: 54.66 | E3: W/407-30008 and 407-30010 and 408-20010 | F3: OK | G3: =VLOOKUP(A3,Sheet2!A:G,7,FALSE) -> 1 | I3: =IF(LEFT(E3,1)="T","Semi-Automatica",IF(LEFT(E3,2)="ST","Maquina",""))
A4: 189-10004 | B4: 50000 | C4: 99999 | D4: 53.28 | E4: W/407-30008 and 407-30010 and 408-20010 | F4: OK | G4: =VLOOKUP(A4,Sheet2!A:G,7,FALSE) -> 1 | I4: =IF(LEFT(E4,1)="T","Semi-Automatica",IF(LEFT(E4,2)="ST","Maquina",""))
A5: 189-10004 | B5: 100000 | C5: 200000 | D5: 50.53 | E5: W/407-30008 and 407-30010 and 408-20010 | F5: OK | G5: =VLOOKUP(A5,Sheet2!A:G,7,FALSE) -> 1 | I5: =IF(LEFT(E5,1)="T","Semi-Automatica",IF(LEFT(E5,2)="ST","Maquina",""))
A6: 189-10005 | B6: 1000 | C6: 10999 | D6: 56.03 | E6: W/407-30008 and 407-30010 and 408-20010 | F6: OK | G6: =VLOOKUP(A6,Sheet2!A:G,7,FALSE) -> 2 | I6: =IF(LEFT(E6,1)="T","Semi-Automatica",IF(LEFT(E6,2)="ST","Maquina",""))
A7: 189-10005 | B7: 11000 | C7: 49999 | D7: 54.66 | E7: W/407-30008 and 407-30010 and 408-20010 | F7: OK | G7: =VLOOKUP(A7,Sheet2!A:G,7,FALSE) -> 2 | I7: =IF(LEFT(E7,1)="T","Semi-Automatica",IF(LEFT(E7,2)="ST","Maquina",""))
A8: 189-10005 | B8: 50000 | C8: 99999 | D8: 53.28 | E8: W/407-30008 and 407-30010 and 408-20010 | F8: OK | G8: =VLOOKUP(A8,Sheet2!A:G,7,FALSE) -> 2 | I8: =IF(LEFT(E8,1)="T","Semi-Automatica",IF(LEFT(E8,2)="ST","Maquina",""))
A9: 189-10005 | B9: 100000 | C9: 200000 | D9: 50.53 | E9: W/407-30008 and 407-30010 and 408-20010 | F9: OK | G9: =VLOOKUP(A9,Sheet2!A:G,7,FALSE) -> 2 | I9: =IF(LEFT(E9,1)="T","Semi-Automatica",IF(LEFT(E9,2)="ST","Maquina",""))
A10: 189-10006 | B10: 1000 | C10: 10999 | D10: 52.58 | F10: OK | G10: =VLOOKUP(A10,Sheet2!A:G,7,FALSE) -> 3 | I10: =IF(LEFT(E10,1)="T","Semi-Automatica",IF(LEFT(E10,2)="ST","Maquina",""))
A11: 189-10006 | B11: 11000 | C11: 49999 | D11: 51.21 | F11: OK | G11: =VLOOKUP(A11,Sheet2!A:G,7,FALSE) -> 3 | I11: =IF(LEFT(E11,1)="T","Semi-Automatica",IF(LEFT(E11,2)="ST","Maquina",""))
A12: 189-10006 | B12: 50000 | C12: 99999 | D12: 49.83 | F12: OK | G12: =VLOOKUP(A12,Sheet2!A:G,7,FALSE) -> 3 | I12: =IF(LEFT(E12,1)="T","Semi-Automatica",IF(LEFT(E12,2)="ST","Maquina",""))
A13: 189-10006 | B13: 100000 | C13: 200000 | D13: 47.08 | F13: OK | G13: =VLOOKUP(A13,Sheet2!A:G,7,FALSE) -> 3 | I13: =IF(LEFT(E13,1)="T","Semi-Automatica",IF(LEFT(E13,2)="ST","Maquina",""))
A14: 189-10009 | B14: 1000 | C14: 10999 | D14: 54.12 | E14: w/ 408-20001 and 408-20012 | F14: OK | G14: =VLOOKUP(A14,Sheet2!A:G,7,FALSE) -> 4 | I14: =IF(LEFT(E14,1)="T","Semi-Automatica",IF(LEFT(E14,2)="ST","Maquina",""))
A15: 189-10009 | B15: 11000 | C15: 49999 | D15: 52.74 | E15: w/ 408-20001 and 408-20012 | F15: OK | G15: =VLOOKUP(A15,Sheet2!A:G,7,FALSE) -> 4 | I15: =IF(LEFT(E15,1)="T","Semi-Automatica",IF(LEFT(E15,2)="ST","Maquina",""))
A16: 189-10009 | B16: 50000 | C16: 99999 | D16: 51.37 | E16: w/ 408-20001 and 408-20012 | F16: OK | G16: =VLOOKUP(A16,Sheet2!A:G,7,FALSE) -> 4 | I16: =IF(LEFT(E16,1)="T","Semi-Automatica",IF(LEFT(E16,2)="ST","Maquina",""))
A17: 189-10009 | B17: 100000 | C17: 200000 | D17: 48.61 | E17: w/ 408-20001 and 408-20012 | F17: OK | G17: =VLOOKUP(A17,Sheet2!A:G,7,FALSE) -> 4 | I17: =IF(LEFT(E17,1)="T","Semi-Automatica",IF(LEFT(E17,2)="ST","Maquina",""))
A18: 189-10010 | B18: 1000 | C18: 10999 | D18: 55.21 | F18: OK | G18: =VLOOKUP(A18,Sheet2!A:G,7,FALSE) -> 5 | I18: =IF(LEFT(E18,1)="T","Semi-Automatica",IF(LEFT(E18,2)="ST","Maquina",""))
A19: 189-10010 | B19: 11000 | C19: 49999 | D19: 53.84 | F19: OK | G19: =VLOOKUP(A19,Sheet2!A:G,7,FALSE) -> 5 | I19: =IF(LEFT(E19,1)="T","Semi-Automatica",IF(LEFT(E19,2)="ST","Maquina",""))
A20: 189-10010 | B20: 50000 | C20: 99999 | D20: 52.46 | F20: OK | G20: =VLOOKUP(A20,Sheet2!A:G,7,FALSE) -> 5 | I20: =IF(LEFT(E20,1)="T","Semi-Automatica",IF(LEFT(E20,2)="ST","Maquina",""))
A21: 189-10010 | B21: 100000 | C21: 200000 | D21: 49.71 | F21: OK | G21: =VLOOKUP(A21,Sheet2!A:G,7,FALSE) -> 5 | I21: =IF(LEFT(E21,1)="T","Semi-Automatica",IF(LEFT(E21,2)="ST","Maquina",""))
A22: 189-10011 | B22: 1000 | C22: 10999 | D22: 53.85 | E22: w/ 407-20013 | F22: OK | G22: =VLOOKUP(A22,Sheet2!A:G,7,FALSE) -> 6 | I22: =IF(LEFT(E22,1)="T","Semi-Automatica",IF(LEFT(E22,2)="ST","Maquina",""))
A23: 189-10011 | B23: 11000 | C23: 49999 | D23: 52.45 | E23: w/ 407-20013 | F23: OK | G23: =VLOOKUP(A23,Sheet2!A:G,7,FALSE) -> 6 | I23: =IF(LEFT(E23,1)="T","Semi-Automatica",IF(LEFT(E23,2)="ST","Maquina",""))
A24: 189-10011 | B24: 50000 | C24: 99999 | D24: 51.06 | E24: w/ 407-20013 | F24: OK | G24: =VLOOKUP(A24,Sheet2!A:G,7,FALSE) -> 6 | I24: =IF(LEFT(E24,1)="T","Semi-Automatica",IF(LEFT(E24,2)="ST","Maquina",""))
A25: 189-10011 | B25: 100000 | C25: 200000 | D25: 48.23 | E25: w/ 407-20013 | F25: OK | G25: =VLOOKUP(A25,Sheet2!A:G,7,FALSE) -> 6 | I25: =IF(LEFT(E25,1)="T","Semi-Automatica",IF(LEFT(E25,2)="ST","Maquina",""))
A26: 189-10012 | B26: 1000 | C26: 10999 | D26: 53.88 | E26: w/ 407-20013 | F26: OK | G26: =VLOOKUP(A26,Sheet2!A:G,7,FALSE) -> 7 | I26: =IF(LEFT(E26,1)="T","Semi-Automatica",IF(LEFT(E26,2)="ST","Maquina",""))
A27: 189-10012 | B27: 11000 | C27: 49999 | D27: 52.47 | E27: w/ 407-20013 | F27: OK | G27: =VLOOKUP(A27,Sheet2!A:G,7,FALSE) -> 7 | I27: =IF(LEFT(E27,1)="T","Semi-Automatica",IF(LEFT(E27,2)="ST","Maquina",""))
A28: 189-10012 | B28: 50000 | C28: 99999 | D28: 51.06 | E28: w/ 407-20013 | F28: OK | G28: =VLOOKUP(A28,Sheet2!A:G,7,FALSE) -> 7 | I28: =IF(LEFT(E28,1)="T","Semi-Automatica",IF(LEFT(E28,2)="ST","Maquina",""))
A29: 189-10012 | B29: 100000 | C29: 200000 | D29: 48.23 | E29: w/ 407-20013 | F29: OK | G29: =VLOOKUP(A29,Sheet2!A:G,7,FALSE) -> 7 | I29: =IF(LEFT(E29,1)="T","Semi-Automatica",IF(LEFT(E29,2)="ST","Maquina",""))
A30: 189-10044 | B30: 1000 | C30: 10999 | D30: 14.99 | E30: BI | F30: OK | G30: =VLOOKUP(A30,Sheet2!A:G,7,FALSE) -> 8 | I30: =IF(LEFT(E30,1)="T","Semi-Automatica",IF(LEFT(E30,2)="ST","Maquina",""))
A31: 189-10044 | B31: 11000 | C31: 49999 | D31: 13.86 | E31: BI | F31: OK | G31: =VLOOKUP(A31,Sheet2!A:G,7,FALSE) -> 8 | I31: =IF(LEFT(E31,1)="T","Semi-Automatica",IF(LEFT(E31,2)="ST","Maquina",""))
A32: 189-10044 | B32: 50000 | C32: 99999 | D32: 12.73 | E32: BI | F32: OK | G32: =VLOOKUP(A32,Sheet2!A:G,7,FALSE) -> 8 | I32: =IF(LEFT(E32,1)="T","Semi-Automatica",IF(LEFT(E32,2)="ST","Maquina",""))
A33: 189-10044 | B33: 100000 | C33: 200000 | D33: 11.31 | E33: BI | F33: OK | G33: =VLOOKUP(A33,Sheet2!A:G,7,FALSE) -> 8 | I33: =IF(LEFT(E33,1)="T","Semi-Automatica",IF(LEFT(E33,2)="ST","Maquina",""))
... A35: 189-10044 | B35: 11000 | C35: 200000 | D35: 0 | E35: T-Machines | F35: OK | G35: =VLOOKUP(A35,Sheet2!A:G,7,FALSE) -> 8 | I35: =IF(LEFT(E35,1)="T","Semi-Automatica",IF(LEFT(E35,2)="ST","Maquina","")) -> Semi-Automatica
A36: 189-10046 | B36: 1000 | C36: 10999 | D36: 13.44 | F36: OK | G36: =VLOOKUP(A36,Sheet2!A:G,7,FALSE) -> 9 | I36: =IF(LEFT(E36,1)="T","Semi-Automatica",IF(LEFT(E36,2)="ST","Maquina",""))
A37: 189-10046 | B37: 11000 | C37: 49999 | D37: 13.09 | F37: OK | G37: =VLOOKUP(A37,Sheet2!A:G,7,FALSE) -> 9 | I37: =IF(LEFT(E37,1)="T","Semi-Automatica",IF(LEFT(E37,2)="ST","Maquina",""))
A38: 189-10046 | B38: 50000 | C38: 99999 | D38: 12.75 | F38: OK | G38: =VLOOKUP(A38,Sheet2!A:G,7,FALSE) -> 9 | I38: =IF(LEFT(E38,1)="T","Semi-Automatica",IF(LEFT(E38,2)="ST","Maquina",""))
A39: 189-10046 | B39: 100000 | C39: 200000 | D39: 12.06 | F39: OK | G39: =VLOOKUP(A39,Sheet2!A:G,7,FALSE) -> 9 | I39: =IF(LEFT(E39,1)="T","Semi-Automatica",IF(LEFT(E39,2)="ST","Maquina",""))
A40: 189-10048 | B40: 1000 | C40: 10999 | D40: 12.61 | F40: OK | G40: =VLOOKUP(A40,Sheet2!A:G,7,FALSE) -> 10 | I40: =IF(LEFT(E40,1)="T","Semi-Automatica",IF(LEFT(E40,2)="ST","Maquina",""))
A41: 189-10048 | B41: 11000 | C41: 49999 | D41: 12.33 | F41: OK | G41: =VLOOKUP(A41,Sheet2!A:G,7,FALSE) -> 10 | I41: =IF(LEFT(E41,1)="T","Semi-Automatica",IF(LEFT(E41,2)="ST","Maquina",""))
...
